10:02:22.11 | ERROR | Fatal Error | Error: Object of type AttributeError is not JSON serializable | Traceback: Traceback (most recent call last):
  File "C:\Users\owner\Desktop\projects\bots\vass\main.py", line 73, in get_quote_price
    raise Exception(json.loads(response.text).dict())
                    ^^^^^^^^^^^^^^^^^^^^^^^^^^^^^^
AttributeError: 'dict' object has no attribute 'dict'

During handling of the above exception, another exception occurred:

Traceback (most recent call last):
  File "C:\Users\owner\Desktop\projects\bots\vass\main.py", line 84, in get_quote_price
    return error_response_model(
           ^^^^^^^^^^^^^^^^^^^^^
  File "C:\Users\owner\Desktop\projects\bots\vass\response.py", line 16, in error_response_model
    return JSONResponse(
           ^^^^^^^^^^^^^
  File "C:\Users\owner\Desktop\projects\bots\vass\venv\Lib\site-packages\starlette\responses.py", line 180, in __init__
    super().__init__(content, status_code, headers, media_type, background)
  File "C:\Users\owner\Desktop\projects\bots\vass\venv\Lib\site-packages\starlette\responses.py", line 43, in __init__
    self.body = self.render(content)
                ^^^^^^^^^^^^^^^^^^^^
  File "C:\Users\owner\Desktop\projects\bots\vass\venv\Lib\site-packages\starlette\responses.py", line 183, in render
    return json.dumps(
           ^^^^^^^^^^^
  File "C:\Program Files\WindowsApps\PythonSoftwareFoundation.Python.3.11_3.11.2544.0_x64__qbz5n2kfra8p0\Lib\json\__init__.py", line 238, in dumps
    **kw).encode(obj)
          ^^^^^^^^^^^
  File "C:\Program Files\WindowsApps\PythonSoftwareFoundation.Python.3.11_3.11.2544.0_x64__qbz5n2kfra8p0\Lib\json\encoder.py", line 200, in encode
    chunks = self.iterencode(o, _one_shot=True)
             ^^^^^^^^^^^^^^^^^^^^^^^^^^^^^^^^^^
  File "C:\Program Files\WindowsApps\PythonSoftwareFoundation.Python.3.11_3.11.2544.0_x64__qbz5n2kfra8p0\Lib\json\encoder.py", line 258, in iterencode
    return _iterencode(o, 0)
           ^^^^^^^^^^^^^^^^^
  File "C:\Program Files\WindowsApps\PythonSoftwareFoundation.Python.3.11_3.11.2544.0_x64__qbz5n2kfra8p0\Lib\json\encoder.py", line 180, in default
    raise TypeError(f'Object of type {o.__class__.__name__} '
TypeError: Object of type AttributeError is not JSON serializable

10:04:13.04 | ERROR | Fatal Error | Error: Object of type AttributeError is not JSON serializable | Traceback: Traceback (most recent call last):
  File "C:\Users\owner\Desktop\projects\bots\vass\main.py", line 70, in get_quote_price
    "status is", data.get("status", None), json.loads(response.text).dict()
                                           ^^^^^^^^^^^^^^^^^^^^^^^^^^^^^^
AttributeError: 'dict' object has no attribute 'dict'

During handling of the above exception, another exception occurred:

Traceback (most recent call last):
  File "C:\Users\owner\Desktop\projects\bots\vass\main.py", line 85, in get_quote_price
    return error_response_model(
           ^^^^^^^^^^^^^^^^^^^^^
  File "C:\Users\owner\Desktop\projects\bots\vass\response.py", line 16, in error_response_model
    return JSONResponse(
           ^^^^^^^^^^^^^
  File "C:\Users\owner\Desktop\projects\bots\vass\venv\Lib\site-packages\starlette\responses.py", line 180, in __init__
    super().__init__(content, status_code, headers, media_type, background)
  File "C:\Users\owner\Desktop\projects\bots\vass\venv\Lib\site-packages\starlette\responses.py", line 43, in __init__
    self.body = self.render(content)
                ^^^^^^^^^^^^^^^^^^^^
  File "C:\Users\owner\Desktop\projects\bots\vass\venv\Lib\site-packages\starlette\responses.py", line 183, in render
    return json.dumps(
           ^^^^^^^^^^^
  File "C:\Program Files\WindowsApps\PythonSoftwareFoundation.Python.3.11_3.11.2544.0_x64__qbz5n2kfra8p0\Lib\json\__init__.py", line 238, in dumps
    **kw).encode(obj)
          ^^^^^^^^^^^
  File "C:\Program Files\WindowsApps\PythonSoftwareFoundation.Python.3.11_3.11.2544.0_x64__qbz5n2kfra8p0\Lib\json\encoder.py", line 200, in encode
    chunks = self.iterencode(o, _one_shot=True)
             ^^^^^^^^^^^^^^^^^^^^^^^^^^^^^^^^^^
  File "C:\Program Files\WindowsApps\PythonSoftwareFoundation.Python.3.11_3.11.2544.0_x64__qbz5n2kfra8p0\Lib\json\encoder.py", line 258, in iterencode
    return _iterencode(o, 0)
           ^^^^^^^^^^^^^^^^^
  File "C:\Program Files\WindowsApps\PythonSoftwareFoundation.Python.3.11_3.11.2544.0_x64__qbz5n2kfra8p0\Lib\json\encoder.py", line 180, in default
    raise TypeError(f'Object of type {o.__class__.__name__} '
TypeError: Object of type AttributeError is not JSON serializable

10:07:25.89 | ERROR | Fatal Error | Error: the JSON object must be str, bytes or bytearray, not ValueError | Traceback: Traceback (most recent call last):
  File "C:\Users\owner\Desktop\projects\bots\vass\main.py", line 72, in get_quote_price
    raise ValueError(data)
ValueError: {'status': '5', 'message': 'No data available', 'data': ''}

During handling of the above exception, another exception occurred:

Traceback (most recent call last):
  File "C:\Users\owner\Desktop\projects\bots\vass\main.py", line 86, in get_quote_price
    "error": json.loads(e),
             ^^^^^^^^^^^^^
  File "C:\Program Files\WindowsApps\PythonSoftwareFoundation.Python.3.11_3.11.2544.0_x64__qbz5n2kfra8p0\Lib\json\__init__.py", line 339, in loads
    raise TypeError(f'the JSON object must be str, bytes or bytearray, '
TypeError: the JSON object must be str, bytes or bytearray, not ValueError

10:07:53.55 | ERROR | Fatal Error | Error: the JSON object must be str, bytes or bytearray, not dict | Traceback: Traceback (most recent call last):
  File "C:\Users\owner\Desktop\projects\bots\vass\main.py", line 72, in get_quote_price
    raise ValueError(data)
ValueError: {'status': '5', 'message': 'No data available', 'data': ''}

During handling of the above exception, another exception occurred:

Traceback (most recent call last):
  File "C:\Users\owner\Desktop\projects\bots\vass\main.py", line 86, in get_quote_price
    "error": json.loads(jsonable_encoder(e)),
             ^^^^^^^^^^^^^^^^^^^^^^^^^^^^^^^
  File "C:\Program Files\WindowsApps\PythonSoftwareFoundation.Python.3.11_3.11.2544.0_x64__qbz5n2kfra8p0\Lib\json\__init__.py", line 339, in loads
    raise TypeError(f'the JSON object must be str, bytes or bytearray, '
TypeError: the JSON object must be str, bytes or bytearray, not dict

10:08:10.59 | ERROR | Fatal Error | Error: Expecting property name enclosed in double quotes: line 1 column 2 (char 1) | Traceback: Traceback (most recent call last):
  File "C:\Users\owner\Desktop\projects\bots\vass\main.py", line 72, in get_quote_price
    raise ValueError(data)
ValueError: {'status': '5', 'message': 'No data available', 'data': ''}

During handling of the above exception, another exception occurred:

Traceback (most recent call last):
  File "C:\Users\owner\Desktop\projects\bots\vass\main.py", line 86, in get_quote_price
    "error": json.loads(str(e)),
             ^^^^^^^^^^^^^^^^^^
  File "C:\Program Files\WindowsApps\PythonSoftwareFoundation.Python.3.11_3.11.2544.0_x64__qbz5n2kfra8p0\Lib\json\__init__.py", line 346, in loads
    return _default_decoder.decode(s)
           ^^^^^^^^^^^^^^^^^^^^^^^^^^
  File "C:\Program Files\WindowsApps\PythonSoftwareFoundation.Python.3.11_3.11.2544.0_x64__qbz5n2kfra8p0\Lib\json\decoder.py", line 337, in decode
    obj, end = self.raw_decode(s, idx=_w(s, 0).end())
               ^^^^^^^^^^^^^^^^^^^^^^^^^^^^^^^^^^^^^^
  File "C:\Program Files\WindowsApps\PythonSoftwareFoundation.Python.3.11_3.11.2544.0_x64__qbz5n2kfra8p0\Lib\json\decoder.py", line 353, in raw_decode
    obj, end = self.scan_once(s, idx)
               ^^^^^^^^^^^^^^^^^^^^^^
json.decoder.JSONDecodeError: Expecting property name enclosed in double quotes: line 1 column 2 (char 1)

10:09:49.34 | ERROR | Fatal Error | Error: Expecting value: line 1 column 1 (char 0) | Traceback: Traceback (most recent call last):
  File "C:\Users\owner\Desktop\projects\bots\vass\main.py", line 85, in get_quote_price
    "error": json.loads(str(e)),
             ^^^^^^^^^^^^^^^^^^
  File "C:\Program Files\WindowsApps\PythonSoftwareFoundation.Python.3.11_3.11.2544.0_x64__qbz5n2kfra8p0\Lib\json\__init__.py", line 346, in loads
    return _default_decoder.decode(s)
           ^^^^^^^^^^^^^^^^^^^^^^^^^^
  File "C:\Program Files\WindowsApps\PythonSoftwareFoundation.Python.3.11_3.11.2544.0_x64__qbz5n2kfra8p0\Lib\json\decoder.py", line 337, in decode
    obj, end = self.raw_decode(s, idx=_w(s, 0).end())
               ^^^^^^^^^^^^^^^^^^^^^^^^^^^^^^^^^^^^^^
  File "C:\Program Files\WindowsApps\PythonSoftwareFoundation.Python.3.11_3.11.2544.0_x64__qbz5n2kfra8p0\Lib\json\decoder.py", line 355, in raw_decode
    raise JSONDecodeError("Expecting value", s, err.value) from None
json.decoder.JSONDecodeError: Expecting value: line 1 column 1 (char 0)

10:10:29.08 | ERROR | Fatal Error | Error: Expecting property name enclosed in double quotes: line 1 column 2 (char 1) | Traceback: Traceback (most recent call last):
  File "C:\Users\owner\Desktop\projects\bots\vass\main.py", line 78, in get_quote_price
    raise Exception({"message": "Bad request. Please try with another data"})
Exception: {'message': 'Bad request. Please try with another data'}

During handling of the above exception, another exception occurred:

Traceback (most recent call last):
  File "C:\Users\owner\Desktop\projects\bots\vass\main.py", line 85, in get_quote_price
    "error": json.loads(str(e)),
             ^^^^^^^^^^^^^^^^^^
  File "C:\Program Files\WindowsApps\PythonSoftwareFoundation.Python.3.11_3.11.2544.0_x64__qbz5n2kfra8p0\Lib\json\__init__.py", line 346, in loads
    return _default_decoder.decode(s)
           ^^^^^^^^^^^^^^^^^^^^^^^^^^
  File "C:\Program Files\WindowsApps\PythonSoftwareFoundation.Python.3.11_3.11.2544.0_x64__qbz5n2kfra8p0\Lib\json\decoder.py", line 337, in decode
    obj, end = self.raw_decode(s, idx=_w(s, 0).end())
               ^^^^^^^^^^^^^^^^^^^^^^^^^^^^^^^^^^^^^^
  File "C:\Program Files\WindowsApps\PythonSoftwareFoundation.Python.3.11_3.11.2544.0_x64__qbz5n2kfra8p0\Lib\json\decoder.py", line 353, in raw_decode
    obj, end = self.scan_once(s, idx)
               ^^^^^^^^^^^^^^^^^^^^^^
json.decoder.JSONDecodeError: Expecting property name enclosed in double quotes: line 1 column 2 (char 1)

10:11:08.49 | ERROR | Fatal Error | Error: Expecting property name enclosed in double quotes: line 1 column 2 (char 1) | Traceback: Traceback (most recent call last):
  File "C:\Users\owner\Desktop\projects\bots\vass\main.py", line 78, in get_quote_price
    raise ValueError(
ValueError: {'message': 'Bad request. Please try with another data or try again later'}

During handling of the above exception, another exception occurred:

Traceback (most recent call last):
  File "C:\Users\owner\Desktop\projects\bots\vass\main.py", line 91, in get_quote_price
    "error": json.loads(str(e)),
             ^^^^^^^^^^^^^^^^^^
  File "C:\Program Files\WindowsApps\PythonSoftwareFoundation.Python.3.11_3.11.2544.0_x64__qbz5n2kfra8p0\Lib\json\__init__.py", line 346, in loads
    return _default_decoder.decode(s)
           ^^^^^^^^^^^^^^^^^^^^^^^^^^
  File "C:\Program Files\WindowsApps\PythonSoftwareFoundation.Python.3.11_3.11.2544.0_x64__qbz5n2kfra8p0\Lib\json\decoder.py", line 337, in decode
    obj, end = self.raw_decode(s, idx=_w(s, 0).end())
               ^^^^^^^^^^^^^^^^^^^^^^^^^^^^^^^^^^^^^^
  File "C:\Program Files\WindowsApps\PythonSoftwareFoundation.Python.3.11_3.11.2544.0_x64__qbz5n2kfra8p0\Lib\json\decoder.py", line 353, in raw_decode
    obj, end = self.scan_once(s, idx)
               ^^^^^^^^^^^^^^^^^^^^^^
json.decoder.JSONDecodeError: Expecting property name enclosed in double quotes: line 1 column 2 (char 1)

10:18:11.02 | ERROR | Error occurred >>> 'RawRequestData' object has no attribute 'proxy' ::::-> __TRACEBACK__ Traceback (most recent call last):
  File "C:\Users\owner\Desktop\projects\bots\vass\utils\views.py", line 15, in start_prep_data
    f"0.1 Task | Cleaning & Processing & Preping Request Data | Proxy: {data.proxy}"
                                                                        ^^^^^^^^^^
  File "C:\Users\owner\Desktop\projects\bots\vass\venv\Lib\site-packages\pydantic\main.py", line 856, in __getattr__
    raise AttributeError(f'{type(self).__name__!r} object has no attribute {item!r}')
AttributeError: 'RawRequestData' object has no attribute 'proxy'
 <<<
10:25:48.73 | ERROR | Fatal Error | Error: Expecting value: line 1 column 1 (char 0) | Traceback: Traceback (most recent call last):
  File "C:\Users\owner\Desktop\projects\bots\vass\main.py", line 74, in get_quote_price
    **json.loads(str(e)),
      ^^^^^^^^^^^^^^^^^^
  File "C:\Program Files\WindowsApps\PythonSoftwareFoundation.Python.3.11_3.11.2544.0_x64__qbz5n2kfra8p0\Lib\json\__init__.py", line 346, in loads
    return _default_decoder.decode(s)
           ^^^^^^^^^^^^^^^^^^^^^^^^^^
  File "C:\Program Files\WindowsApps\PythonSoftwareFoundation.Python.3.11_3.11.2544.0_x64__qbz5n2kfra8p0\Lib\json\decoder.py", line 337, in decode
    obj, end = self.raw_decode(s, idx=_w(s, 0).end())
               ^^^^^^^^^^^^^^^^^^^^^^^^^^^^^^^^^^^^^^
  File "C:\Program Files\WindowsApps\PythonSoftwareFoundation.Python.3.11_3.11.2544.0_x64__qbz5n2kfra8p0\Lib\json\decoder.py", line 355, in raw_decode
    raise JSONDecodeError("Expecting value", s, err.value) from None
json.decoder.JSONDecodeError: Expecting value: line 1 column 1 (char 0)

10:27:27.29 | ERROR | Fatal Error | Error: Expecting value: line 1 column 1 (char 0) | Traceback: Traceback (most recent call last):
  File "C:\Users\owner\Desktop\projects\bots\vass\main.py", line 74, in get_quote_price
    **json.loads(str(e)),
      ^^^^^^^^^^^^^^^^^^
  File "C:\Program Files\WindowsApps\PythonSoftwareFoundation.Python.3.11_3.11.2544.0_x64__qbz5n2kfra8p0\Lib\json\__init__.py", line 346, in loads
    return _default_decoder.decode(s)
           ^^^^^^^^^^^^^^^^^^^^^^^^^^
  File "C:\Program Files\WindowsApps\PythonSoftwareFoundation.Python.3.11_3.11.2544.0_x64__qbz5n2kfra8p0\Lib\json\decoder.py", line 337, in decode
    obj, end = self.raw_decode(s, idx=_w(s, 0).end())
               ^^^^^^^^^^^^^^^^^^^^^^^^^^^^^^^^^^^^^^
  File "C:\Program Files\WindowsApps\PythonSoftwareFoundation.Python.3.11_3.11.2544.0_x64__qbz5n2kfra8p0\Lib\json\decoder.py", line 355, in raw_decode
    raise JSONDecodeError("Expecting value", s, err.value) from None
json.decoder.JSONDecodeError: Expecting value: line 1 column 1 (char 0)

15:04:52.89 | ERROR | Fatal Error | Error: Expecting value: line 1 column 1 (char 0) | Traceback: Traceback (most recent call last):
  File "C:\Users\owner\Desktop\projects\bots\vass\main.py", line 74, in get_quote_price
    **json.loads(str(e)),
      ^^^^^^^^^^^^^^^^^^
  File "C:\Program Files\WindowsApps\PythonSoftwareFoundation.Python.3.11_3.11.2544.0_x64__qbz5n2kfra8p0\Lib\json\__init__.py", line 346, in loads
    return _default_decoder.decode(s)
           ^^^^^^^^^^^^^^^^^^^^^^^^^^
  File "C:\Program Files\WindowsApps\PythonSoftwareFoundation.Python.3.11_3.11.2544.0_x64__qbz5n2kfra8p0\Lib\json\decoder.py", line 337, in decode
    obj, end = self.raw_decode(s, idx=_w(s, 0).end())
               ^^^^^^^^^^^^^^^^^^^^^^^^^^^^^^^^^^^^^^
  File "C:\Program Files\WindowsApps\PythonSoftwareFoundation.Python.3.11_3.11.2544.0_x64__qbz5n2kfra8p0\Lib\json\decoder.py", line 355, in raw_decode
    raise JSONDecodeError("Expecting value", s, err.value) from None
json.decoder.JSONDecodeError: Expecting value: line 1 column 1 (char 0)

15:10:10.28 | ERROR | Fatal Error | Error: Expecting value: line 1 column 1 (char 0) | Traceback: Traceback (most recent call last):
  File "C:\Users\owner\Desktop\projects\bots\vass\main.py", line 75, in get_quote_price
    **json.loads(str(e)),
      ^^^^^^^^^^^^^^^^^^
  File "C:\Program Files\WindowsApps\PythonSoftwareFoundation.Python.3.11_3.11.2544.0_x64__qbz5n2kfra8p0\Lib\json\__init__.py", line 346, in loads
    return _default_decoder.decode(s)
           ^^^^^^^^^^^^^^^^^^^^^^^^^^
  File "C:\Program Files\WindowsApps\PythonSoftwareFoundation.Python.3.11_3.11.2544.0_x64__qbz5n2kfra8p0\Lib\json\decoder.py", line 337, in decode
    obj, end = self.raw_decode(s, idx=_w(s, 0).end())
               ^^^^^^^^^^^^^^^^^^^^^^^^^^^^^^^^^^^^^^
  File "C:\Program Files\WindowsApps\PythonSoftwareFoundation.Python.3.11_3.11.2544.0_x64__qbz5n2kfra8p0\Lib\json\decoder.py", line 355, in raw_decode
    raise JSONDecodeError("Expecting value", s, err.value) from None
json.decoder.JSONDecodeError: Expecting value: line 1 column 1 (char 0)

15:16:06.37 | SUCCESS | 0.1 Task | Cleaning & Processing & Preping Request Data | Proxy: 212.83.143.204:40663
15:16:06.37 | SUCCESS | 0.0 Process | Initiating Scrapper Class On Selenium
15:16:06.37 | SUCCESS | 1.0 Process | Starting Driver
15:16:11.40 | ERROR | Proxy check failed SOCKSHTTPConnectionPool(host='ip-api.com', port=80): Max retries exceeded with url: /json (Caused by ConnectTimeoutError(<urllib3.contrib.socks.SOCKSConnection object at 0x0000024BE7328450>, 'Connection to ip-api.com timed out. (connect timeout=5)')) | Traceback: Traceback (most recent call last):
  File "C:\Users\owner\Desktop\projects\bots\vass\venv\Lib\site-packages\socks.py", line 787, in connect
    super(socksocket, self).connect(proxy_addr)
TimeoutError: timed out

During handling of the above exception, another exception occurred:

Traceback (most recent call last):
  File "C:\Users\owner\Desktop\projects\bots\vass\venv\Lib\site-packages\urllib3\contrib\socks.py", line 110, in _new_conn
    conn = socks.create_connection(
           ^^^^^^^^^^^^^^^^^^^^^^^^
  File "C:\Users\owner\Desktop\projects\bots\vass\venv\Lib\site-packages\socks.py", line 209, in create_connection
    raise err
  File "C:\Users\owner\Desktop\projects\bots\vass\venv\Lib\site-packages\socks.py", line 199, in create_connection
    sock.connect((remote_host, remote_port))
  File "C:\Users\owner\Desktop\projects\bots\vass\venv\Lib\site-packages\socks.py", line 47, in wrapper
    return function(*args, **kwargs)
           ^^^^^^^^^^^^^^^^^^^^^^^^^
  File "C:\Users\owner\Desktop\projects\bots\vass\venv\Lib\site-packages\socks.py", line 800, in connect
    raise ProxyConnectionError(msg, error)
socks.ProxyConnectionError: Error connecting to SOCKS4 proxy 212.83.143.204:40663: timed out

The above exception was the direct cause of the following exception:

Traceback (most recent call last):
  File "C:\Users\owner\Desktop\projects\bots\vass\venv\Lib\site-packages\urllib3\connectionpool.py", line 789, in urlopen
    response = self._make_request(
               ^^^^^^^^^^^^^^^^^^^
  File "C:\Users\owner\Desktop\projects\bots\vass\venv\Lib\site-packages\urllib3\connectionpool.py", line 495, in _make_request
    conn.request(
  File "C:\Users\owner\Desktop\projects\bots\vass\venv\Lib\site-packages\urllib3\connection.py", line 441, in request
    self.endheaders()
  File "C:\Program Files\WindowsApps\PythonSoftwareFoundation.Python.3.11_3.11.2544.0_x64__qbz5n2kfra8p0\Lib\http\client.py", line 1298, in endheaders
    self._send_output(message_body, encode_chunked=encode_chunked)
  File "C:\Program Files\WindowsApps\PythonSoftwareFoundation.Python.3.11_3.11.2544.0_x64__qbz5n2kfra8p0\Lib\http\client.py", line 1058, in _send_output
    self.send(msg)
  File "C:\Program Files\WindowsApps\PythonSoftwareFoundation.Python.3.11_3.11.2544.0_x64__qbz5n2kfra8p0\Lib\http\client.py", line 996, in send
    self.connect()
  File "C:\Users\owner\Desktop\projects\bots\vass\venv\Lib\site-packages\urllib3\connection.py", line 279, in connect
    self.sock = self._new_conn()
                ^^^^^^^^^^^^^^^^
  File "C:\Users\owner\Desktop\projects\bots\vass\venv\Lib\site-packages\urllib3\contrib\socks.py", line 134, in _new_conn
    raise ConnectTimeoutError(
urllib3.exceptions.ConnectTimeoutError: (<urllib3.contrib.socks.SOCKSConnection object at 0x0000024BE7328450>, 'Connection to ip-api.com timed out. (connect timeout=5)')

The above exception was the direct cause of the following exception:

Traceback (most recent call last):
  File "C:\Users\owner\Desktop\projects\bots\vass\venv\Lib\site-packages\requests\adapters.py", line 667, in send
    resp = conn.urlopen(
           ^^^^^^^^^^^^^
  File "C:\Users\owner\Desktop\projects\bots\vass\venv\Lib\site-packages\urllib3\connectionpool.py", line 843, in urlopen
    retries = retries.increment(
              ^^^^^^^^^^^^^^^^^^
  File "C:\Users\owner\Desktop\projects\bots\vass\venv\Lib\site-packages\urllib3\util\retry.py", line 519, in increment
    raise MaxRetryError(_pool, url, reason) from reason  # type: ignore[arg-type]
    ^^^^^^^^^^^^^^^^^^^^^^^^^^^^^^^^^^^^^^^^^^^^^^^^^^^
urllib3.exceptions.MaxRetryError: SOCKSHTTPConnectionPool(host='ip-api.com', port=80): Max retries exceeded with url: /json (Caused by ConnectTimeoutError(<urllib3.contrib.socks.SOCKSConnection object at 0x0000024BE7328450>, 'Connection to ip-api.com timed out. (connect timeout=5)'))

During handling of the above exception, another exception occurred:

Traceback (most recent call last):
  File "C:\Users\owner\Desktop\projects\bots\vass\utils\scrapper.py", line 501, in check_proxy
    response = requests.get(
               ^^^^^^^^^^^^^
  File "C:\Users\owner\Desktop\projects\bots\vass\venv\Lib\site-packages\requests\api.py", line 73, in get
    return request("get", url, params=params, **kwargs)
           ^^^^^^^^^^^^^^^^^^^^^^^^^^^^^^^^^^^^^^^^^^^^
  File "C:\Users\owner\Desktop\projects\bots\vass\venv\Lib\site-packages\requests\api.py", line 59, in request
    return session.request(method=method, url=url, **kwargs)
           ^^^^^^^^^^^^^^^^^^^^^^^^^^^^^^^^^^^^^^^^^^^^^^^^^
  File "C:\Users\owner\Desktop\projects\bots\vass\venv\Lib\site-packages\requests\sessions.py", line 589, in request
    resp = self.send(prep, **send_kwargs)
           ^^^^^^^^^^^^^^^^^^^^^^^^^^^^^^
  File "C:\Users\owner\Desktop\projects\bots\vass\venv\Lib\site-packages\requests\sessions.py", line 703, in send
    r = adapter.send(request, **kwargs)
        ^^^^^^^^^^^^^^^^^^^^^^^^^^^^^^^
  File "C:\Users\owner\Desktop\projects\bots\vass\venv\Lib\site-packages\requests\adapters.py", line 688, in send
    raise ConnectTimeout(e, request=request)
requests.exceptions.ConnectTimeout: SOCKSHTTPConnectionPool(host='ip-api.com', port=80): Max retries exceeded with url: /json (Caused by ConnectTimeoutError(<urllib3.contrib.socks.SOCKSConnection object at 0x0000024BE7328450>, 'Connection to ip-api.com timed out. (connect timeout=5)'))

15:16:32.30 | SUCCESS | 0.1 Task | Cleaning & Processing & Preping Request Data | Proxy: None
15:16:32.30 | SUCCESS | 0.0 Process | Initiating Scrapper Class On Selenium
15:16:32.30 | SUCCESS | 1.0 Process | Starting Driver
15:16:32.60 | ERROR | Proxy is in the wrong country
15:19:30.49 | SUCCESS | 0.1 Task | Cleaning & Processing & Preping Request Data | Proxy: 212.83.137.94:54561
15:19:30.49 | SUCCESS | 0.0 Process | Initiating Scrapper Class On Selenium
15:19:30.49 | SUCCESS | 1.0 Process | Starting Driver
15:19:37.26 | SUCCESS | 1.1 Attempt 1 to load the page.
15:19:56.46 | SUCCESS | 1.2 Page loaded successfully.
15:19:57.62 | ERROR | Error occurred >>> 'SubRequestData' object has no attribute 'veicolo' ::::-> __TRACEBACK__ Traceback (most recent call last):
  File "C:\Users\owner\Desktop\projects\bots\vass\utils\views.py", line 47, in start_prep_data
    return BotScrapper(data, db).start()
           ^^^^^^^^^^^^^^^^^^^^^^^^^^^^^
  File "C:\Users\owner\Desktop\projects\bots\vass\utils\scrapper.py", line 630, in start
    value=data.veicolo.targa,
          ^^^^^^^^^^^^
  File "C:\Users\owner\Desktop\projects\bots\vass\venv\Lib\site-packages\pydantic\main.py", line 856, in __getattr__
    raise AttributeError(f'{type(self).__name__!r} object has no attribute {item!r}')
AttributeError: 'SubRequestData' object has no attribute 'veicolo'
 <<<
15:20:53.36 | SUCCESS | 0.1 Task | Cleaning & Processing & Preping Request Data | Proxy: 212.83.137.94:54561
15:20:53.36 | SUCCESS | 0.0 Process | Initiating Scrapper Class On Selenium
15:20:53.36 | SUCCESS | 1.0 Process | Starting Driver
15:20:56.02 | SUCCESS | 1.1 Attempt 1 to load the page.
15:21:12.68 | SUCCESS | 1.2 Page loaded successfully.
15:21:15.00 | INFO | reCAPTCHA info found: {'callback': "___grecaptcha_cfg.clients['0']['A']['A']['callback']", 'function': {}, 'id': '0', 'sitekey': '6LcTvwsaAAAAACrX9g0kYHzox2v3VG8E4E9omeYm', 'version': 'V2'}
15:21:30.25 | SUCCESS | Solved captcha: 03AFcWeA5F4IOeTDS7Knv010iRbVogvlHmDls72bWvrsFAQR_WPTmYrGR3lof3ClJsWG73Nqs6nVsD3-CWDwH-G-xy2X2PC1hbUD4B6EgDL3R_MhX_-v6v0XXND-vIZmVeD36CO0oEHnuVCEfFzACNyUGECfYDen4dTD_DEk83lmEN9QT1p8kjnB__B8OCANJv3HmKp2uyKuuQwPpbVicjUMsdEUCEjyF1vRD2nTQEBLI9R2mSThe2eNnpUbjw2qoU1IBaKt0CYueALLFqDXfMERxrcAO4bScaIYAiFrT5dMgSIveeqoOBIfl9lL8O1ao8ULUuodjkCiTsI9CEb57eIZ0Zo9Y2pMAErJVEIq8fV0iWiQHDnC9AZKNYoBirHDLt9S-IhwPL4GPXU1V-CQYfuwgPrVECXHJNA9nH37fm3gJmp53iZjboCs9R8Z6PerN76kxt8GVdjWkVdEdz1jpcTqLJgTprhYwTF6EY81uUqrC-CwaOv3eVnriMtLyGyG-FgRNoKbfsLhaa-DfPKQ8_XZvzWPSEjTUrnqcywP_N4VbIIGbPqoMfH4IaFVQk8cQi1zsX-p9094N2RtIND0rsWk2POA0jqa5mKk0jWpvArEHrMzrCH-rfSPYWhKbv4TkiW3VwJUGX4u4gvvui-pI7AhcSoflKW9HdRwPD3OUO0ujfLbPxkuu2v57_ONOKH5AyqBiGWXRIZpYJs185tBFRiCe2Lb1snkbyu6z9TgC1p8BVKVnpVgHZk9kP8X7rOVdUv6LBBhy_BTgpEcrSyfYnwFsKfpryPv-w4X8x7E8q9G6k-M4O0yCBXcrUrNbmfjw_cw3svBR4K6WKgFm_kd9ASvrleSpNsU8_mbe3PeXws8K3nzWQHi4kobiGJ4h1bzhM3ozteo_Xm63u4EaybTsMOIg371U_IloGofLM4yMFOw6uKNK0dlK0kHGs96BERhRI-1CFRWy5ml56
15:23:31.31 | SUCCESS | Terminating Session
